<?xml version="1.0" ?>
<!-- =================================================================================== -->
<!-- |    This document was autogenerated by xacro from /home/tracelab/RobotUnified_v2/Test_IK/Robot.xacro | -->
<!-- |    EDITING THIS FILE BY HAND IS NOT RECOMMENDED                                 | -->
<!-- =================================================================================== -->
<robot name="five_dof_cobot_rollJ4">
  <!-- EE í”Œëžœì§€~íˆ´íŒ ì˜¤í”„ì…‹ -->
  <!-- ê·¸ë¦¬í¼ ë¶€ë¶„ ê¸°ì–´ ì¤‘ì‹¬ - ê·¸ë¦¬í¼ ëë‹¨ ê¹Œì§€ ê±°ë¦¬ 85.97mm -->
  <!-- ðŸ”´FILL -->
  <!-- ðŸ”´FILL -->
  <!-- ðŸ”´FILL -->
  <!-- ë§í¬ ìƒ‰ìƒ(Material) -->
  <material name="mat_base">
    <color rgba="0.25 0.25 0.25 1.0"/>
  </material>
  <material name="mat_l1">
    <color rgba="0.85 0.10 0.10 1.0"/>
  </material>
  <material name="mat_l2">
    <color rgba="0.10 0.55 0.90 1.0"/>
  </material>
  <material name="mat_l3">
    <color rgba="0.10 0.75 0.25 1.0"/>
  </material>
  <material name="mat_l4">
    <color rgba="0.90 0.60 0.10 1.0"/>
  </material>
  <material name="mat_l5">
    <color rgba="0.60 0.20 0.90 1.0"/>
  </material>
  <material name="mat_ee">
    <color rgba="0.90 0.90 0.90 1.0"/>
  </material>
  <!-- ========== ë§í¬ ì •ì˜ ========== -->
  <link name="base_link">
    <visual>
      <geometry>
        <cylinder length="0.04" radius="0.08"/>
      </geometry>
      <material name="mat_base"/>
    </visual>
    <collision>
      <geometry>
        <cylinder length="0.04" radius="0.08"/>
      </geometry>
    </collision>
    <inertial>
      <origin rpy="0 0 0" xyz="0 0 0"/>
      <mass value="4.113"/>
      <!-- ðŸ”´FILL -->
      <inertia ixx="0.0332" ixy="0" ixz="0" iyy="0.12002" iyz="0" izz="0.12021"/>
      <!-- ðŸ”´FILL -->
    </inertial>
  </link>
  <link name="link1">
    <visual>
      <origin rpy="0 0 0" xyz="0 0 0.067305"/>
      <geometry>
        <cylinder length="0.13461" radius="0.05"/>
      </geometry>
      <material name="mat_l1"/>
    </visual>
    <collision>
      <origin rpy="0 0 0" xyz="0 0 0.067305"/>
      <geometry>
        <cylinder length="0.13461" radius="0.05"/>
      </geometry>
    </collision>
    <inertial>
      <origin rpy="0 0 0" xyz="0 0 0.067305"/>
      <mass value="3.183"/>
      <inertia ixx="0.02" ixy="0" ixz="0" iyy="0.04" iyz="0" izz="0.06"/>
    </inertial>
  </link>
  <link name="link2">
    <visual>
      <origin rpy="0 0 0" xyz="0.02375 0 0"/>
      <geometry>
        <box size="0.0475 0.05 0.05"/>
      </geometry>
      <material name="mat_l2"/>
    </visual>
    <collision>
      <origin rpy="0 0 0" xyz="0.02375 0 0"/>
      <geometry>
        <box size="0.0475 0.05 0.05"/>
      </geometry>
    </collision>
    <inertial>
      <origin rpy="0 0 0" xyz="0.02375 0 0"/>
      <mass value="0.23"/>
      <inertia ixx="0.01" ixy="0" ixz="0" iyy="0.03" iyz="0" izz="0.05"/>
    </inertial>
  </link>
  <link name="link3">
    <visual>
      <origin rpy="0 0 0" xyz="0.0375 0 0"/>
      <geometry>
        <box size="0.075 0.045 0.045"/>
      </geometry>
      <material name="mat_l3"/>
    </visual>
    <collision>
      <origin rpy="0 0 0" xyz="0.0375 0 0"/>
      <geometry>
        <box size="0.075 0.045 0.045"/>
      </geometry>
    </collision>
    <inertial>
      <origin rpy="0 0 0" xyz="0.0375 0 0"/>
      <mass value="0.4"/>
      <inertia ixx="0.002" ixy="0" ixz="0" iyy="0.02" iyz="0" izz="0.01"/>
    </inertial>
  </link>
  <link name="link4">
    <visual>
      <origin rpy="0 0 0" xyz="0.12084 0 0"/>
      <geometry>
        <box size="0.24168 0.04 0.04"/>
      </geometry>
      <material name="mat_l4"/>
    </visual>
    <collision>
      <origin rpy="0 0 0" xyz="0.12084 0 0"/>
      <geometry>
        <box size="0.24168 0.04 0.04"/>
      </geometry>
    </collision>
    <inertial>
      <origin rpy="0 0 0" xyz="0.12084 0 0"/>
      <mass value="0.2"/>
      <inertia ixx="0.001" ixy="0" ixz="0" iyy="0.03" iyz="0" izz="0.002"/>
    </inertial>
  </link>
  <link name="link5">
    <visual>
      <origin rpy="0 0 0" xyz="0 0 0"/>
      <geometry>
        <box size="0.05 0.04 0.04"/>
      </geometry>
      <material name="mat_l5"/>
    </visual>
    <collision>
      <origin rpy="0 0 0" xyz="0 0 0"/>
      <geometry>
        <box size="0.05 0.04 0.04"/>
      </geometry>
    </collision>
    <inertial>
      <origin rpy="0 0 0" xyz="0 0 0"/>
      <mass value="0.1"/>
      <inertia ixx="0.0002" ixy="0" ixz="0" iyy="0.0002" iyz="0" izz="0.0002"/>
    </inertial>
  </link>
  <link name="ee_link">
    <visual>
      <origin rpy="0 0 0" xyz="0.042985 0 0"/>
      <geometry>
        <cylinder length="0.08597" radius="0.02"/>
      </geometry>
      <material name="mat_ee"/>
    </visual>
    <collision>
      <origin rpy="0 0 0" xyz="0.042985 0 0"/>
      <geometry>
        <cylinder length="0.08597" radius="0.02"/>
      </geometry>
    </collision>
  </link>
  <!-- ========== ì¡°ì¸íŠ¸ ì •ì˜ (ì¶• ë°©í–¥ ê³ ì •) ========== -->
  <!-- J1: Base Yaw (ì¢Œìš° íšŒì „, zì¶•) -->
  <joint name="joint1_base_yaw" type="revolute">
    <parent link="base_link"/>
    <child link="link1"/>
    <origin rpy="0 0 0" xyz="0 0 0"/>
    <axis xyz="0 0 1"/>
    <limit effort="101.2" lower="-3.14159" upper="3.14159" velocity="2.5"/>
    <!-- ðŸ”´FILL -->
  </joint>
  <!-- J2: Shoulder Pitch (ìœ„/ì•„ëž˜, yì¶•) -->
  <joint name="joint2_shoulder_pitch" type="revolute">
    <parent link="link1"/>
    <child link="link2"/>
    <origin rpy="0 0 0" xyz="0 0 0.13461"/>
    <axis xyz="0 1 0"/>
    <limit effort="33.6" lower="-2.61799" upper="2.61799" velocity="2.5"/>
    <!-- ðŸ”´FILL -->
  </joint>
  <!-- J3: Elbow Pitch (ìœ„/ì•„ëž˜, yì¶•) -->
  <joint name="joint3_elbow_pitch" type="revolute">
    <parent link="link2"/>
    <child link="link3"/>
    <origin rpy="0 0 0" xyz="0.0475 0 0"/>
    <axis xyz="0 1 0"/>
    <limit effort="33.6" lower="-2.61799" upper="2.61799" velocity="2.5"/>
    <!-- ðŸ”´FILL -->
  </joint>
  <!-- âœ… J4: Wrist ROLL (ë¹„í‹€ê¸°, xì¶•) -->
  <joint name="joint4_wrist_roll" type="revolute">
    <parent link="link3"/>
    <child link="link4"/>
    <origin rpy="0 0 0" xyz="0.075 0 0"/>
    <axis xyz="1 0 0"/>
    <limit effort="33.6" lower="-3.14159" upper="3.14159" velocity="2.5"/>
    <!-- ðŸ”´FILL -->
  </joint>
  <!-- J5: Wrist Pitch (ìœ„/ì•„ëž˜, yì¶•) -->
  <joint name="joint5_wrist_pitch" type="revolute">
    <parent link="link4"/>
    <child link="link5"/>
    <origin rpy="0 0 0" xyz="0.24168 0 0"/>
    <axis xyz="0 1 0"/>
    <limit effort="25.2" lower="-2.61799" upper="2.61799" velocity="2.5"/>
    <!-- ðŸ”´FILL -->
  </joint>
  <!-- EE ê³ ì • -->
  <joint name="joint_ee_fixed" type="fixed">
    <parent link="link5"/>
    <child link="ee_link"/>
    <origin rpy="0 0 0" xyz="0 0 0"/>
  </joint>
  <!-- (ì„ íƒ) ros2_controlìš© transmission/ros2_control ë¸”ë¡ì€ ì‹¤ì œ êµ¬ë™ ìŠ¤íŽ™ í™•ì • í›„ ì¶”ê°€ -->
</robot>
